<?xml version='1.0'?>
<sdf version="1.5">
  <model name="isabelle">
      <pose>0 0 0 0 0 0</pose>
      <static>false</static>
        <link name="base_link">
          <inertial>
                <mass>2.26796</mass>
                <pose>0 0 0 0 0 0</pose>
                <inertia>
                    <ixx>0.03462</ixx>
                    <ixy>0</ixy>
                    <ixz>0</ixz>
                    <iyy>0.03462</iyy>
                    <iyz>0</iyz>
                    <izz>0.03462</izz>
                </inertia>
          </inertial>
          <collision name="collision">
            <geometry>
              <box>
                <size>.254 .1524 .04</size>
              </box>
            </geometry>
          </collision>

          <visual name="visual">
            <geometry>
              <box>
                <size>.254 .1524 .04</size>
              </box>
            </geometry>
          </visual>
        </link>
       
      <link name="back_left_caster">
        <pose>.09779 -.09 -.01079 0 1.5707 1.5707</pose>
          <inertial>
                <mass>0.45</mass>
                <pose>0 0 0 0 0 0</pose>
                <inertia>
                    <ixx>0.01536</ixx>
                    <ixy>0</ixy>
                    <ixz>0</ixz>
                    <iyy>0.01536</iyy>
                    <iyz>0</iyz>
                    <izz>0.01536</izz>
                </inertia>
          </inertial>
        <collision name="back_left_collision">
          <geometry>
            <sphere>
             <radius>.02921"</radius>
            </sphere>
          </geometry>
          <surface>
                <friction>
                    <ode>
                    <mu>0.0</mu>
                    <mu2>0.0</mu2>
                    </ode>
                </friction>
          </surface>
        </collision>

        <visual name="back_left_visual">
          <geometry>
            <sphere>
              <radius>.02921"</radius>
            </sphere>
          </geometry>
        </visual>

      </link>
      
      <joint type="revolute" name="back_left_caster_hinge">
        <pose>0 0 0 -1.5707 0 0</pose>
        <child>back_left_caster</child>
        <parent>base_link</parent>
        <axis>
          <xyz>0 1 0</xyz>
        </axis>
      </joint>

      <link name="back_right_caster">
        <pose>.09779 .09 -.01079 0 1.5707 1.5707</pose>
          <inertial>
                <mass>0.45</mass>
                <pose>0 0 0 0 0 0</pose>
                <inertia>
                    <ixx>0.01536</ixx>
                    <ixy>0</ixy>
                    <ixz>0</ixz>
                    <iyy>0.01536</iyy>
                    <iyz>0</iyz>
                    <izz>0.01536</izz>
                </inertia>
          </inertial>
        <collision name="back_right_collision">
          <geometry>
            <sphere>
             <radius>.02921"</radius>
            </sphere>
          </geometry>
          <surface>
                <friction>
                    <ode>
                    <mu>0.0</mu>
                    <mu2>0.0</mu2>
                    </ode>
                </friction>
          </surface>
        </collision>

        <visual name="back_right_visual">
          <geometry>
            <sphere>
             <radius>.02921"</radius>
            </sphere>
          </geometry>
        </visual>

      </link>


      <joint type="revolute" name="back_right_caster_hinge">
        <pose>0 0 0 -1.5707 0 0</pose>
        <child>back_right_caster</child>
        <parent>base_link</parent>
        <axis>
          <xyz>0 1 0</xyz>
        </axis>
      </joint>

      <link name="front_left_wheel">
        <pose>-0.09779 -0.09 -.01079 0 1.5707 1.5707</pose>
          <inertial>
                <mass>0.45</mass>
                <pose>0 0 0 0 0 0</pose>
                <inertia>
                    <ixx>0.00007</ixx>
                    <ixy>0</ixy>
                    <ixz>0</ixz>
                    <iyy>0.00007</iyy>
                    <iyz>0</iyz>
                    <izz>0.000018375</izz>
                </inertia>
          </inertial>
        <collision name="front_left_collision">
          <geometry>
            <cylinder>
              <radius>.02921</radius>
              <length>.0254</length>
            </cylinder>
          </geometry>
          <surface>
            <friction>
                <ode>
                <mu>1.0</mu>
                <mu2>1.0</mu2>
                <slip1>0.0</slip1>
                <slip2>0.0</slip2>
                </ode>
            </friction>
          </surface>
        </collision>
        
        <visual name="front_left_visual">
          <geometry>
            <cylinder>
              <radius>.02921</radius>
              <length>.0254</length>
            </cylinder>
          </geometry>
        </visual>
      
      </link>

      <joint type="revolute" name="front_left_wheel_hinge">
        <pose>0 0 0 -1.5707 0 0</pose>
        <child>front_left_wheel</child>
        <parent>base_link</parent>
        <axis>
          <xyz>0 1 0</xyz>
        </axis>
      </joint>

      <link name="front_right_wheel">
        <pose>-0.09779 0.09 -.01079 0 1.5707 1.5707</pose>
          <inertial>
                <mass>0.45</mass>
                <pose>0 0 0 0 0 0</pose>
                <inertia>
                    <ixx>0.00007</ixx>
                    <ixy>0</ixy>
                    <ixz>0</ixz>
                    <iyy>0.00007</iyy>
                    <iyz>0</iyz>
                    <izz>0.000018375</izz>
                </inertia>
          </inertial>
        <collision name="front_right_collision">
          <geometry>
            <cylinder>
              <radius>.02921</radius>
              <length>.0254</length>
            </cylinder>
          </geometry>
            <surface>
            <friction>
                <ode>
                <mu>1.0</mu>
                <mu2>1.0</mu2>
                <slip1>0.0</slip1>
                <slip2>0.0</slip2>
                </ode>
            </friction>
            </surface>
        </collision>

        <visual name="front_right_visual">
          <geometry>
            <cylinder>
              <radius>.02921</radius>
              <length>.0254</length>
            </cylinder>
          </geometry>
        </visual>
      
      </link>

      <joint type="revolute" name="front_right_wheel_hinge">
        <pose>0 0 0 -1.5707 0 0</pose>
        <child>front_right_wheel</child>
        <parent>base_link</parent>
        <axis>
          <xyz>0 1 0</xyz>
        </axis>      
      </joint>
    
    <link name = "imu_link">
      <pose> 0 0 0</pose>
      <visual name = "imu_visual">
        <geometry>
          <box>
            <size> 0.01 0.01 0.01 </size>
          </box>
        </geometry>
      </visual>
      
      <collision name = "imu_collision">
        <geometry>
          <box>
            <size> 0.01 0.01 0.01 </size>
          </box>
        </geometry>
      </collision>

      <sensor name = "imu_sensor" type = "imu">
        <always_on>true</always_on>
        <plugin filename = "libgazebo_ros_imu_sensor.so" name = "imu_plugin">
          <robotNamespace>isabelle</robotNamespace>
          <topicName>imu</topicName>
          <updateRateHZ>30</updateRateHZ>
          <frameName>imu_link</frameName>
          <initialOrientationAsReference>false</initialOrientationAsReference>
        </plugin>
      </sensor>
    </link>
    
    <joint name ="imu_joint" type ="fixed">
      <parent>base_link</parent>
      <child>imu_link</child>
    </joint>    

    <link name = "hokuyo_link">
      <pose>0 0 0.0481 0 0 3.14</pose>
        <collision name = "hokuyo_collision">
          <geometry> 
            <box>
              <size>0.0508 0.0508 0.0762</size>
            </box>
          </geometry>
        </collision>

        <visual name = "hokuyo_visual">
          <geometry> 
            <box>
              <size>0.0508 0.0508 0.0762</size>
            </box>
          </geometry>
        </visual>

        <sensor type = "ray" name = "hokuyo_sensor">
          <visualize>true</visualize>
          <updateRate>40</updateRate>
          <ray>
            <scan>
              <horizontal>
                <samples>1080</samples>
                <resolution>0.25</resolution>
                <min_angle>-2.3561945</min_angle>
                <max_angle>2.3561945</max_angle>
              </horizontal>
            </scan>
            <range> 
              <min>0.10</min>
              <max>30</max>
              <resolution>0.01</resolution>
            </range>
            <noise>
              <type>gaussian</type>
              <mean>0.0</mean>
              <stddev>0.01</stddev>
            </noise>
          </ray>
          
          <plugin name = "hokuyo_plugin" filename = "libgazebo_ros_laser.so">
            <topicName>isabelle/laserscan</topicName>
            <frameName>hokuyo_link</frameName>
          </plugin>
        </sensor>
    </link>

    <joint name = "hokuyo_joint" type = "fixed">
      <child>hokuyo_link</child>
      <parent>base_link</parent>
    </joint>

    <plugin filename="libgazebo_ros_diff_drive.so" name="diff_drive_controller">
      <robotNamespace>isabelle</robotNamespace>
      <rosDebugLevel>debug</rosDebugLevel>
      <!-- 'physical' characteristics -->
      <leftJoint>front_left_wheel_hinge</leftJoint>
      <rightJoint>front_right_wheel_hinge</rightJoint>
      <wheelSeparation>0.1524</wheelSeparation>
      <wheelDiameter>0.05842</wheelDiameter>
      <wheelTorque>1.5</wheelTorque>
      <!-- in Nm -->
      <!-- plugin characteristics -->
      <odometrySource>encoder</odometrySource>
      <publishOdom>true</publishOdom>
      <updateRate>100</updateRate>
      <!-- tf -->
      <publishTf>true</publishTf>
      <!-- publish the transforms -->
      <publishOdomTF>true</publishOdomTF>
      <publishWheelTF>false</publishWheelTF>
      <odometryFrame>/odom</odometryFrame>
      <robotBaseFrame>base_link</robotBaseFrame>
      <!-- ros messaging -->
      <commandTopic>/cmd_vel</commandTopic>
      <!-- listens to -->
      <odometryTopic>/odom</odometryTopic>
      <!-- publishes on -->
      <!-- Set to true to swap right and left wheels, defaults to true -->
      <legacyMode>false</legacyMode>
    </plugin>
  
  </model>
</sdf>
