<?xml version='1.0'?>
<sdf version="1.5">
  <model name="isabelle">
      <pose>0 0 0 0 0 0</pose>
      <static>false</static>
        <link name="chassis">
          <collision name="collision">
            <geometry>
              <box>
                <size>.254 .1524 .04</size>
              </box>
            </geometry>
          </collision>

          <visual name="visual">
            <geometry>
              <box>
                <size>.254 .1524 .04</size>
              </box>
            </geometry>
          </visual>
        </link>
       
      <link name="back_left_wheel">
        <pose>-.09779 -.09 -.01079 0 1.5707 1.5707</pose>
          <inertial>
                <mass>0.45</mass>
                <pose>0 0 0 0 0 0</pose>
                <inertia>
                    <ixx>0.00007</ixx>
                    <ixy>0</ixy>
                    <ixz>0</ixz>
                    <iyy>0.00007</iyy>
                    <iyz>0</iyz>
                    <izz>0.000018375</izz>
                </inertia>
          </inertial>
        <collision name="back_left_collision">
          <geometry>
            <cylinder>
              <radius>.02921</radius>
              <length>.0254</length>
            </cylinder>
          </geometry>
          <surface>
                <friction>
                    <ode>
                    <mu>100000.0</mu>
                    <mu2>100000.0</mu2>
                    <slip1>0.0</slip1>
                    <slip2>0.0</slip2>
                    </ode>
                </friction>
          </surface>
        </collision>

        <visual name="back_left_visual">
          <geometry>
            <cylinder>
              <radius>.02921</radius>
              <length>.0254</length>
            </cylinder>
          </geometry>
        </visual>

      </link>
      
      <joint type="revolute" name="back_left_wheel_hinge">
        <pose>0 0 0 -1.5707 0 0</pose>
        <child>back_left_wheel</child>
        <parent>chassis</parent>
        <axis>
          <xyz>0 1 0</xyz>
        </axis>
      </joint>

      <link name="back_right_wheel">
        <pose>-.09779 .09 -.01079  0 1.5707 1.5707</pose>
          <inertial>
                <mass>0.45</mass>
                <pose>0 0 0 0 0 0</pose>
                <inertia>
                    <ixx>0.00007</ixx>
                    <ixy>0</ixy>
                    <ixz>0</ixz>
                    <iyy>0.00007</iyy>
                    <iyz>0</iyz>
                    <izz>0.000018375</izz>
                </inertia>
          </inertial>
        <collision name="back_right_collision">
          <geometry>
            <cylinder>
              <radius>.02921</radius>
              <length>.0254</length>
            </cylinder>
          </geometry>
          <surface>
            <friction>
                <ode>
                <mu>100000.0</mu>
                <mu2>100000.0</mu2>
                <slip1>0.0</slip1>
                <slip2>0.0</slip2>
                </ode>
            </friction>
          </surface>
        </collision>
        
        <visual name="back_right_visual">
          <geometry>
            <cylinder>
              <radius>.02921</radius>
              <length>.0254</length>
            </cylinder>
          </geometry>
        </visual>
      
      </link>


      <joint type="revolute" name="back_right_wheel_hinge">
        <pose>0 0 0 -1.5707 0 0</pose>
        <child>back_right_wheel</child>
        <parent>chassis</parent>
        <axis>
          <xyz>0 1 0</xyz>
        </axis>
      </joint>

      <link name="front_left_wheel">
        <pose>.09779 -0.09 -.01079 0 1.5707 1.5707</pose>
          <inertial>
                <mass>0.45</mass>
                <pose>0 0 0 0 0 0</pose>
                <inertia>
                    <ixx>0.00007</ixx>
                    <ixy>0</ixy>
                    <ixz>0</ixz>
                    <iyy>0.00007</iyy>
                    <iyz>0</iyz>
                    <izz>0.000018375</izz>
                </inertia>
          </inertial>
        <collision name="front_left_collision">
          <geometry>
            <cylinder>
              <radius>.02921</radius>
              <length>.0254</length>
            </cylinder>
          </geometry>
          <surface>
            <friction>
                <ode>
                <mu>100000.0</mu>
                <mu2>100000.0</mu2>
                <slip1>0.0</slip1>
                <slip2>0.0</slip2>
                </ode>
            </friction>
          </surface>
        </collision>
        
        <visual name="front_left_visual">
          <geometry>
            <cylinder>
              <radius>.02921</radius>
              <length>.0254</length>
            </cylinder>
          </geometry>
        </visual>
      
      </link>

      <joint type="revolute" name="front_left_wheel_hinge">
        <pose>0 0 0 -1.5707 0 0</pose>
        <child>front_left_wheel</child>
        <parent>chassis</parent>
        <axis>
          <xyz>0 1 0</xyz>
        </axis>
      </joint>

      <link name="front_right_wheel">
        <pose>.09779 0.09 -.01079 0 1.5707 1.5707</pose>
          <inertial>
                <mass>0.45</mass>
                <pose>0 0 0 0 0 0</pose>
                <inertia>
                    <ixx>0.00007</ixx>
                    <ixy>0</ixy>
                    <ixz>0</ixz>
                    <iyy>0.00007</iyy>
                    <iyz>0</iyz>
                    <izz>0.000018375</izz>
                </inertia>
          </inertial>
        <collision name="front_right_collision">
          <geometry>
            <cylinder>
              <radius>.02921</radius>
              <length>.0254</length>
            </cylinder>
          </geometry>
            <surface>
            <friction>
                <ode>
                <mu>100000.0</mu>
                <mu2>100000.0</mu2>
                <slip1>0.0</slip1>
                <slip2>0.0</slip2>
                </ode>
            </friction>
            </surface>
        </collision>

        <visual name="front_right_visual">
          <geometry>
            <cylinder>
              <radius>.02921</radius>
              <length>.0254</length>
            </cylinder>
          </geometry>
        </visual>
      
      </link>

      <joint type="revolute" name="front_right_wheel_hinge">
        <pose>0 0 0 -1.5707 0 0</pose>
        <child>front_right_wheel</child>
        <parent>chassis</parent>
        <axis>
          <xyz>0 1 0</xyz>
        </axis>      
      </joint>
    
    <link name = "imu_link">
      <pose> -0.1 0 0.045</pose>
      <visual name = "imu_visual">
        <geometry>
          <box>
            <size> 0.01 0.01 0.01 </size>
          </box>
        </geometry>
      </visual>
      
      <collision name = "imu_collision">
        <geometry>
          <box>
            <size> 0.01 0.01 0.01 </size>
          </box>
        </geometry>
      </collision>

      <sensor name = "imu_sensor" type = "imu">
        <always_on>true</always_on>
        <plugin filename = "libgazebo_ros_imu_sensor.so" name = "imu_plugin">
          <robotNamespace>isabelle</robotNamespace>
          <topicName>imu</topicName>
          <updateRateHZ>30</updateRateHZ>
          <frameName>imu_link</frameName>
          <initialOrientationAsReference>false</initialOrientationAsReference>
        </plugin>
      </sensor>
    </link>
    
    <joint name ="imu_joint" type ="fixed">
      <parent>chassis</parent>
      <child>imu_link</child>
    </joint>
    
    <link name = "camera_link">
      <pose>-0.1 0.0 0.03 0 0 0</pose>
      <collision name = "camera_collision">
        <geometry> 
          <box> 
          <size> 0.02 0.09 0.02 </size> 
          </box> 
        </geometry> 
      </collision> 
      
      <visual name = "camera_visual">
        <geometry> 
        	<box> 
          	<size> 0.02 0.09 0.02 </size> 
          </box> 
        </geometry>
      </visual>
      
      <sensor type = "camera" name = "camera">      	
      	<always_on>0</always_on>
        <updateRate>20</updateRate>

        <camera name="camera">
         	<horizontal_fov>0.03703703704</horizontal_fov>
          <image>
          	<width>640</width>
            <height>480</height>
          </image>
          <clip>
          	<near>0.5</near>
            <far>2</far>
          </clip>
          <distortion>
            <k1>0.0</k1>
            <k2>0.0</k2>
            <k3>0.0</k3>
            <p1>0.0</p1>
            <p2>0.0</p2>
            <center>0.0 0.0</center>
          </distortion>
        </camera>
        
        <plugin name="camera_controller" filename="libgazebo_ros_camera.so">
        <alwaysOn>true</alwaysOn>
        <updateRate>0.0</updateRate>
        <cameraName>isabelle/camera</cameraName>
        <imageTopicName>image</imageTopicName>
        <cameraInfoTopicName>camera_info</cameraInfoTopicName>
        <frameName>camera_link</frameName>
        <hackBaseline>0.07</hackBaseline>
          <distortionK1>0.0</distortionK1>
          <distortionK2>0.0</distortionK2>
          <distortionK3>0.0</distortionK3>
          <distortionT1>0.0</distortionT1>
          <distortionT2>0.0</distortionT2>
        </plugin>

      </sensor>
    </link>

    <joint name="camera_joint" type="fixed">
      <child>camera_link</child>
      <parent>chassis</parent>
    </joint>    

    <link name = "hokuyo_link">
      <pose>0 0 0.0481 0 0 1.5708</pose>
        <collision name = "hokuyo_collision">
          <geometry> 
            <box>
              <size>0.0508 0.0508 0.0762</size>
            </box>
          </geometry>
        </collision>

        <visual name = "hokuyo_visual">
          <geometry> 
            <box>
              <size>0.0508 0.0508 0.0762</size>
            </box>
          </geometry>
        </visual>

        <sensor type = "ray" name = "hokuyo_sensor">
          <visualize>false</visualize>
          <updateRate>40</updateRate>
          <ray>
            <scan>
              <horizontal>
                <samples>1080</samples>
                <resolution>0.25</resolution>
                <min_angle>-2.3561945</min_angle>
                <max_angle>2.3561945</max_angle>
              </horizontal>
            </scan>
            <range> 
              <min>0.10</min>
              <max>30</max>
              <resolution>0.01</resolution>
            </range>
            <noise>
              <type>gaussian</type>
              <mean>0.0</mean>
              <stddev>0.01</stddev>
            </noise>
          </ray>
          
          <plugin name = "hokuyo_plugin" filename = "libgazebo_ros_laser.so">
            <topicName>isabelle/laserscan</topicName>
            <frameName>hokuyo_link</frameName>
          </plugin>
        </sensor>
    </link>

    <joint name = "hokuyo_joint" type = "fixed">
      <child>hokuyo_link</child>
      <parent>chassis</parent>
    </joint>

    <plugin name="skid_steer_drive_controller" filename="libgazebo_ros_skid_steer_drive.so">
      <robotNamespace>isabelle</robotNamespace>
      <rosDebugLevel>debug</rosDebugLevel>

      <leftFrontJoint>front_left_wheel_hinge</leftFrontJoint>
      <rightFrontJoint>front_right_wheel_hinge</rightFrontJoint>
      <leftRearJoint>back_left_wheel_hinge</leftRearJoint>
      <rightRearJoint>back_right_wheel_hinge</rightRearJoint>
      <wheelSeparation>0.1524</wheelSeparation>
      <wheelDiameter>0.05842</wheelDiameter>
      <torque>1.5</torque>

      <odometrySource>world</odometrySource> 
      <publishOdom>true</publishOdom> 
      <updateRate>100</updateRate>
      <publishOdomTF>false</publishOdomTF>
      <publishWheelTF>true</publishWheelTF>
      <odometryFrame>odom</odometryFrame>

      <robotBaseFrame>chassis</robotBaseFrame>
      <topicName>cmd_vel</topicName>
      <publishTf>true</publishTf>
    </plugin>
  
  </model>
</sdf>
